<?xml version="1.0"?>

<!-- units are in SI -->
<robot name="harpy">

    <!-- *************************** MATERIALS *************************** -->
    <material name="black">
        <color rgba="0.2 0.2 0.2 1"/>
    </material>
    <material name="caltech_orange">
        <color rgba="0.92 0.39 0.043 1"/>
    </material>
    
    <!-- *************************** LINKS *************************** -->
    <!-- Ground -->
    <link name="ground">
        <inertial>  <!-- dummy inertia: ground is welded to the world frame -->
            <mass value="1"/>
            <inertia ixx="0.0001" ixy="0" ixz="0" iyy="0.0001" iyz="0" izz="0.0001"/>
        </inertial>
        <collision>
            <origin rpy="0 0 0" xyz="0 0 -50"/>
            <geometry>
                <box size="100 100 100"/>
            </geometry>
        </collision>
    </link>

    <!-- Torso -->
    <link name="Torso">
        <inertial>
            <origin rpy="0 0 0" xyz="0.08081922 0.00039877 -0.01702118"/>
            <mass value="3.2677"/>
            <inertia ixx="0.05031174" ixy="0.00048513" ixz="-0.00001617" 
                     iyy="0.02068285" iyz="-0.00006038" izz="0.05619613"/>   
        </inertial>
        <visual>
            <geometry>
                <mesh filename="../meshes/Torso.obj"/>
            </geometry>
            <material name="black"/>
        </visual>
        <collision>
            <origin rpy="0 0 0" xyz="0 0 0.15"/>
            <geometry>
                <sphere radius="0.17"/>
            </geometry>
        </collision>
    </link>

    <!-- FrontalHip -->
    <link name="FrontalHipRight">
        <inertial>
            <origin rpy="-1.57 0 0" xyz="0 -0.03048 0.02167"/>
            <mass value="0.16423"/>
            <inertia ixx="0.0002216588" ixy="-1.3E-10" ixz="-1.8E-10" iyy="0.0001625677" iyz="-0.0000760325" izz="0.0001434828"/>   
        </inertial>
        <visual>
            <geometry>
                <mesh filename="../meshes/HipCouplingRight.obj"/>
            </geometry>
            <material name="black"/>
        </visual>
    </link>
    <link name="FrontalHipLeft">
        <inertial>
            <origin rpy="1.57 0 0" xyz="0.0 0.03048 0.02167"/>
            <mass value="0.16423"/>
            <inertia ixx="0.0002216588" ixy="-1.3E-10" ixz="-1.8E-10" iyy="0.0001625677" iyz="0.0000760325" izz="0.0001434828"/>   
        </inertial>
        <visual>
            <geometry>
                <mesh filename="../meshes/HipCouplingLeft.obj"/>
            </geometry>
            <material name="black"/>
        </visual>
    </link>

    <!-- Hip -->
    <link name="SagittalHipRight">
        <inertial>
            <origin rpy="0 0 -1.2" xyz="-0.04421902 -0.06615100 0.02343725"/>
            <mass value="0.62604160"/>
            <inertia ixx="0.00276505" ixy="0.00153900" ixz="-0.00000512" iyy="0.00149602" iyz="-0.00000768" izz="0.00359441"/>   
        </inertial>
        <visual>
            <geometry>
                <mesh filename="../meshes/HipRight.obj"/>
            </geometry>
            <material name="black"/>
        </visual>
    </link>
    <link name="SagittalHipLeft">
        <inertial>
            <origin rpy="0 0 -1.2" xyz="0.04586521 0.06502045 -0.02343725"/>
            <mass value="0.62604160"/>
            <inertia ixx="0.0026909813" ixy="0.00156749" ixz="-0.00000533" iyy="0.00157009" iyz="-0.00000753" izz="0.00359441"/>   
        </inertial>
        <visual>
            <geometry>
                <mesh filename="../meshes/HipLeft.obj"/>
            </geometry>
            <material name="black"/>
        </visual>
    </link>

    <!-- Knee -->
    <link name="KneeRight">
        <inertial>
            <origin rpy="0 0 -1.35" xyz="-0.097517 0.06879 0.006394"/>
            <mass value="0.13046943"/>
            <inertia ixx="0.00079103" ixy="-0.00084157" ixz="-0.00002123" iyy="0.00095844" iyz="-0.00001923" izz="0.00173789"/>   
        </inertial>
        <visual>
            <geometry>
                <mesh filename="../meshes/KneeRight.obj"/>
            </geometry>
            <material name="black"/>
        </visual>
    </link>
    <link name="KneeLeft">
        <inertial>
            <origin rpy="0 0 0.2" xyz="0.06879 0.097517 -0.006394"/>
            <mass value="0.13046943"/>
            <inertia ixx="0.00079103" ixy="-0.00084157" ixz="-0.00002123" iyy="0.00095844" iyz="-0.00001923" izz="0.00173789"/>   
        </inertial>
        <visual>
            <geometry>
                <mesh filename="../meshes/KneeLeft.obj"/>
            </geometry>
            <material name="black"/>
        </visual>
    </link>

    <!-- Ankle -->
    <link name="AnkleRight">
        <inertial>
            <origin rpy="0 0 1.04" xyz="-0.02193081 -0.01265732 -0.00002585"/>
            <mass value="0.07857811"/>
            <inertia ixx="0.00009120" ixy="0.00014304" ixz="-0.00000008" iyy="0.00025640" iyz="-0.00000010" izz="0.00033557"/>   
        </inertial>
        <visual>
            <geometry>
                <mesh filename="../meshes/AnkleRight.obj"/>
            </geometry>
            <material name="black"/>
        </visual>
    </link>
    <link name="AnkleLeft">
        <inertial>
            <origin rpy="0 0 2.094" xyz="0.01265732 0.02193081 0.00002585"/>
            <mass value="0.07857811"/>
            <inertia ixx="0.00025640" ixy="0.00014304" ixz="-0.00000010" iyy="0.00009120" iyz="-0.00000008" izz="0.00033557"/>   
        </inertial>
        <visual>
            <geometry>
                <mesh filename="../meshes/AnkleLeft.obj"/>
            </geometry>
            <material name="black"/>
        </visual>
    </link>

    <!-- Foot -->
    <link name="FootRight">
        <inertial>
            <origin rpy="0 0 0" xyz="0.0 -0.01428958 0.0"/>
            <mass value="0.02387642"/>
            <inertia ixx="0.00000158" ixy="0.0" ixz="0.0" iyy="0.00001558" iyz="0.0" izz="0.00001677"/>   
        </inertial>
        <visual>
            <!-- <geometry>
                <mesh filename="../meshes/Foot.obj"/>
            </geometry> -->
            <geometry>
                <sphere radius="0.01"/>
            </geometry>
            <material name="caltech_orange"/> 
        </visual>
        <collision>
            <origin rpy="0 0 0" xyz="0.0 0.0 0.0"/>
            <geometry>
                <sphere radius="0.01"/>
            </geometry>
        </collision>
    </link>
    <link name="FootLeft">
        <inertial>
            <origin rpy="0 0 0" xyz="0.0 -0.01428958 0.0"/>
            <mass value="0.02387642"/>
            <inertia ixx="0.00000158" ixy="0.0" ixz="0.0" iyy="0.00001558" iyz="0.0" izz="0.00001677"/>   
        </inertial>
        <visual>
            <!-- <geometry>
                <mesh filename="../meshes/Foot.obj"/>
            </geometry> -->
            <geometry>
                <sphere radius="0.01"/>
            </geometry>
            <material name="caltech_orange"/>
        </visual>
        <collision>
            <origin rpy="0 0 0" xyz="0.0 0.0 0.0"/>
            <geometry>
                <sphere radius="0.01"/>
            </geometry>
        </collision>
    </link>

    <!-- Thruster -->
    <link name="ThrusterRight">
        <inertial>
            <origin rpy="0 0 0" xyz="0.0 0.0 -0.00964905"/>
            <mass value="0.49"/>
            <inertia ixx="0.00011044" ixy="0.0" ixz="0.0" iyy="0.00011045" iyz="0.0" izz="0.00009201"/>   
        </inertial>
        <visual>
            <geometry>
                <mesh filename="../meshes/ThrusterRight.obj"/>
            </geometry>
            <material name="black"/>
        </visual>
    </link>    
    <link name="ThrusterLeft">
        <inertial>
            <origin rpy="0 0 0" xyz="0.0 0.0 -0.00964905"/>
            <mass value="0.49"/>
            <inertia ixx="0.00011044" ixy="0.0" ixz="0.0" iyy="0.00011045" iyz="0.0" izz="0.00009201"/>   
        </inertial>
        <visual>
            <geometry>
                <mesh filename="../meshes/ThrusterLeft.obj"/>
            </geometry>
            <material name="black"/>
        </visual>
    </link>  

    <!--Shockabsorber link-->
    <link name="SARight"/>  <!-- Right upper ball frame -->
    <link name="FSARight"/> <!-- Right lower ball frame -->
    
    <!--FootSA Link-->
    <link name="SALeft"/>   <!-- Left upper ball frame -->
    <link name="FSALeft"/>  <!-- Left lower ball frame -->

    <!-- *************************** JOINTS *************************** -->
    <!-- Ground to world-->
    <joint name="world_joint" type="fixed">
        <parent link="world"/>
        <child link="ground"/>
        <origin xyz="0.0 0.0 0.0" rpy="0.0 0.0 0.0"/>
    </joint>

    <!-- Base frame to torso -->
    <joint name="FloatingBase" type="planar">
        <parent link="ground"/>
        <child link="Torso"/>
        <axis xyz="0 -1 0"/>
        <origin xyz="0.0 0.0 0.0" rpy="0.0 -1.5708 -3.1416"/>
    </joint>

    <!-- Upperbody to frontal (USED ON HARDWARE) -->
    <joint name="FrontalRightJoint" type="fixed">
        <parent link="Torso"/>
        <child link="FrontalHipRight"/>
        <axis xyz="0 0 -1"/>
        <origin xyz="0.0 0.1 0.03140" rpy="0.0 0.0 0.0"/>
    </joint>
    <joint name="FrontalLeftJoint" type="fixed">
        <parent link="Torso"/>
        <child link="FrontalHipLeft"/>
        <axis xyz="0 0 -1"/>
        <origin xyz="0.0 -0.1 0.03140" rpy="0.0 0.0 0.0"/>
    </joint>

    <!-- Frontal to Sagittal (USED ON HARDWARE) -->
    <joint name="SagittalRightJoint" type="continuous">
        <parent link="FrontalHipRight"/>
        <child link="SagittalHipRight"/>
        <axis xyz="0 0 1"/>
        <origin xyz="0.0 0.0 0.06405" rpy="1.57 1.57 0.0"/>
    </joint>
    <joint name="SagittalLeftJoint" type="continuous">
        <parent link="FrontalHipLeft"/>
        <child link="SagittalHipLeft"/>
        <axis xyz="0 0 1"/>
        <origin xyz="0.0 0.0 0.06405" rpy="1.57 -1.57 0"/>
    </joint>

    <!--Sagittal to Knee (USED ON HARDWARE) -->
    <joint name="KneeRightJoint" type="continuous">
        <parent link="SagittalHipRight"/>
        <child link="KneeRight"/>
        <axis xyz="0 0 1"/>
        <origin xyz="-0.08531 -0.12761 0.05941" rpy="3.14 0.0 1.57"/>
    </joint>
    <joint name="KneeLeftJoint" type="continuous">
        <parent link="SagittalHipLeft"/>
        <child link="KneeLeft"/>
        <axis xyz="0 0 1"/>
        <origin xyz="0.08531 0.12761 -0.05941  " rpy="3.14 0.0 -3.14"/>
    </joint>
  
    <!-- Ankle to foot -->
    <joint name="FootRightJoint" type="continuous">
        <parent link="AnkleRight"/>
        <child link="FootRight"/>
        <axis xyz="0 0 1"/>
        <origin xyz="-0.11258 -0.065  0.0 " rpy="0.0 0.0 -1.57"/>
    </joint>
    <joint name="FootLeftJoint" type="continuous">
        <parent link="AnkleLeft"/>
        <child link="FootLeft"/>
        <axis xyz="0 0 -1"/>
        <origin xyz="0.065 0.11258 0.0"  rpy="0.0 0.0 3.14"/>
    </joint>

    <!-- Knee to Ankle-->
    <joint name="AnkleRightJoint" type="continuous">
        <parent link="KneeRight"/>
        <child link="AnkleRight"/>
        <axis xyz="0 0 1"/>
        <origin xyz="-0.26067 0.18387 0.00787 " rpy="0.0 0.0 0.0"/>
    </joint>
    <joint name="AnkleLeftJoint" type="continuous">
        <parent link="KneeLeft"/>
        <child link="AnkleLeft"/>
        <axis xyz="0 0 -1"/>
        <origin xyz="0.18387 0.26067  -0.00787"  rpy="3.14 0.0 -3.14"/>
    </joint>

    <!-- Torso to thrusters-->
    <joint name="ThrusterRightJoint" type="fixed">
        <parent link="Torso"/>
        <child link="ThrusterRight"/>
        <axis xyz="0 1 0"/>
        <origin xyz="0.101 0.25 0.0 " rpy="0.0 1.57 0.0"/>
    </joint>
    <joint name="ThrusterLeftJoint" type="fixed">
        <parent link="Torso"/>
        <child link="ThrusterLeft"/>
        <axis xyz="0 1 0"/>
        <origin xyz="0.101 -0.25 0.0"  rpy="0.0 1.57 0.0"/>
    </joint>

    <!-- Hip to SA (Right) - Right upper ball frame (POS FIXED) --> 
    <joint name="SARightJoint" type="fixed">
        <parent link="SagittalHipRight"/>
        <child link="SARight"/>
        <origin xyz="-0.05195 -0.07640 0.0511" rpy="0 1.5708 3.14159"/>
    </joint>
    <!--Foot to SA (Right) - Right lower ball frame (POS FIXED)--> 
    <joint name="FSARightJoint" type="fixed">
        <parent link="AnkleRight"/>
        <child link="FSARight"/>
        <origin xyz="0.05196 0.03 0.0" rpy="-1.5708 0.0 -1.5708"/>
    </joint>
 
    <!-- Hip to SA (Left) - Left upper ball frame (POS FIXED) -->
    <joint name="SALeftJoint" type="fixed">
        <parent link="SagittalHipLeft"/>
        <child link="SALeft"/>
        <origin xyz="0.05195 0.07640 -0.0511" rpy="0.0 0.0 0.0"/>
    </joint>
    <!--Foot to SA (Left) - Left lower ball frame (POS FIXED)-->
    <joint name="FSALeftJoint" type="fixed">
        <parent link="AnkleLeft"/>
        <child link="FSALeft"/>
        <origin xyz="-0.03 -0.05196 0.0" rpy="1.5708 0.0 0"/>
    </joint>

    <!-- *************************** ACTUATORS *************************** -->
    
    <!-- Right Leg, FrontalHip > SaggitalHip > Knee > Ankle-->
    <transmission name="SagittalRightJoint">
        <type>transmission_interface/SimpleTransmission</type>
        <joint name="SagittalRightJoint"/>
        <actuator name="SagittalRightJoint"/>
    </transmission>
    <transmission name="KneeRightJoint">
        <type>transmission_interface/SimpleTransmission</type>
        <joint name="KneeRightJoint"/>
        <actuator name="KneeRightJoint"/>
    </transmission>
    <transmission name="AnkleRightJoint">
        <type>transmission_interface/SimpleTransmission</type>
        <joint name="AnkleRightJoint"/>
        <actuator name="AnkleRightJoint"/>
    </transmission>
    <transmission name="FootRightJoint">
        <type>transmission_interface/SimpleTransmission</type>
        <joint name="FootRightJoint"/>
        <actuator name="FootRightJoint"/>
    </transmission>

    <!-- Left Leg, FrontalHip > SaggitalHip > Knee > Ankle-->
    <transmission name="SagittalLeftJoint">
        <type>transmission_interface/SimpleTransmission</type>
        <joint name="SagittalLeftJoint"/>
        <actuator name="SagittalLeftJoint"/>
    </transmission>
    <transmission name="KneeLeftJoint">
        <type>transmission_interface/SimpleTransmission</type>
        <joint name="KneeLeftJoint"/>
        <actuator name="KneeLeftJoint"/>
    </transmission>
    <transmission name="AnkleLeftJoint">
        <type>transmission_interface/SimpleTransmission</type>
        <joint name="AnkleLeftJoint"/>
        <actuator name="AnkleLeftJoint"/>
    </transmission>
    <transmission name="FootLeftJoint">
        <type>transmission_interface/SimpleTransmission</type>
        <joint name="FootLeftJoint"/>
        <actuator name="FootLeftJoint"/>
    </transmission>
    
</robot>
